Traceback (most recent call last):
  File "/usr/share/miniconda/envs/q2book/lib/python3.6/site-packages/nbclient/client.py", line 609, in _async_poll_for_reply
    msg = await ensure_async(self.kc.shell_channel.get_msg(timeout=new_timeout))
  File "/usr/share/miniconda/envs/q2book/lib/python3.6/site-packages/nbclient/util.py", line 85, in ensure_async
    result = await obj
  File "/usr/share/miniconda/envs/q2book/lib/python3.6/site-packages/jupyter_client/asynchronous/channels.py", line 48, in get_msg
    raise Empty
queue.Empty

During handling of the above exception, another exception occurred:

Traceback (most recent call last):
  File "/usr/share/miniconda/envs/q2book/lib/python3.6/site-packages/jupyter_cache/executors/utils.py", line 56, in single_nb_execution
    record_timing=False,
  File "/usr/share/miniconda/envs/q2book/lib/python3.6/site-packages/nbclient/client.py", line 1087, in execute
    return NotebookClient(nb=nb, resources=resources, km=km, **kwargs).execute()
  File "/usr/share/miniconda/envs/q2book/lib/python3.6/site-packages/nbclient/util.py", line 74, in wrapped
    return just_run(coro(*args, **kwargs))
  File "/usr/share/miniconda/envs/q2book/lib/python3.6/site-packages/nbclient/util.py", line 53, in just_run
    return loop.run_until_complete(coro)
  File "/usr/share/miniconda/envs/q2book/lib/python3.6/asyncio/base_events.py", line 488, in run_until_complete
    return future.result()
  File "/usr/share/miniconda/envs/q2book/lib/python3.6/site-packages/nbclient/client.py", line 541, in async_execute
    cell, index, execution_count=self.code_cells_executed + 1
  File "/usr/share/miniconda/envs/q2book/lib/python3.6/site-packages/nbclient/client.py", line 816, in async_execute_cell
    exec_reply = await self.task_poll_for_reply
  File "/usr/share/miniconda/envs/q2book/lib/python3.6/site-packages/nbclient/client.py", line 633, in _async_poll_for_reply
    await self._async_handle_timeout(timeout, cell)
  File "/usr/share/miniconda/envs/q2book/lib/python3.6/site-packages/nbclient/client.py", line 684, in _async_handle_timeout
    "Cell execution timed out", timeout, cell
nbclient.exceptions.CellTimeoutError: A cell timed out while it was being executed, after 120 seconds.
The message was: Cell execution timed out.
Here is a preview of the cell contents:
-------------------
['# compute all kmers for the specified alphabet', 'W = compute_W(alphabet, k)', '', '# Define a function that returns the taxonomy at a specified level given', '# a semi-colon separated taxonomic description.']
...
['', '# Build a table of the kmer frequencies as a pandas.DataFrame object, and then ', '# display the first 25 rows of that table.', 'per_sequence_kmer_counts = pd.DataFrame(data=per_sequence_kmer_counts).fillna(0).T', 'per_sequence_kmer_counts[:25]']
-------------------

