Traceback (most recent call last):
  File "/usr/share/miniconda/envs/q2book/lib/python3.6/site-packages/jupyter_cache/executors/utils.py", line 56, in single_nb_execution
    record_timing=False,
  File "/usr/share/miniconda/envs/q2book/lib/python3.6/site-packages/nbclient/client.py", line 1087, in execute
    return NotebookClient(nb=nb, resources=resources, km=km, **kwargs).execute()
  File "/usr/share/miniconda/envs/q2book/lib/python3.6/site-packages/nbclient/util.py", line 74, in wrapped
    return just_run(coro(*args, **kwargs))
  File "/usr/share/miniconda/envs/q2book/lib/python3.6/site-packages/nbclient/util.py", line 53, in just_run
    return loop.run_until_complete(coro)
  File "/usr/share/miniconda/envs/q2book/lib/python3.6/asyncio/base_events.py", line 488, in run_until_complete
    return future.result()
  File "/usr/share/miniconda/envs/q2book/lib/python3.6/site-packages/nbclient/client.py", line 541, in async_execute
    cell, index, execution_count=self.code_cells_executed + 1
  File "/usr/share/miniconda/envs/q2book/lib/python3.6/site-packages/nbclient/client.py", line 832, in async_execute_cell
    self._check_raise_for_error(cell, exec_reply)
  File "/usr/share/miniconda/envs/q2book/lib/python3.6/site-packages/nbclient/client.py", line 740, in _check_raise_for_error
    raise CellExecutionError.from_cell_and_msg(cell, exec_reply['content'])
nbclient.exceptions.CellExecutionError: An error occurred while executing the following cell:
------------------
sequence_polar_ordination = polar_ordination(sequence_distance_matrix)
sequence_polar_ordination
------------------

[0;31m---------------------------------------------------------------------------[0m
[0;31mAttributeError[0m                            Traceback (most recent call last)
[0;32m<ipython-input-22-c9e6a8b3929a>[0m in [0;36m<module>[0;34m[0m
[0;32m----> 1[0;31m [0msequence_polar_ordination[0m [0;34m=[0m [0mpolar_ordination[0m[0;34m([0m[0msequence_distance_matrix[0m[0;34m)[0m[0;34m[0m[0;34m[0m[0m
[0m[1;32m      2[0m [0msequence_polar_ordination[0m[0;34m[0m[0;34m[0m[0m

[0;32m<ipython-input-21-3f6ec354d33c>[0m in [0;36mpolar_ordination[0;34m(dm)[0m
[1;32m      8[0m             [0mresult[0m[0;34m.[0m[0mappend[0m[0;34m([0m[0mcompute_axis[0m[0;34m([0m[0mdm[0m[0;34m,[0m [0mid1[0m[0;34m,[0m [0mid2[0m[0;34m)[0m [0;34m)[0m[0;34m[0m[0;34m[0m[0m
[1;32m      9[0m     [0mresult[0m [0;34m=[0m [0mpd[0m[0;34m.[0m[0mconcat[0m[0;34m([0m[0mresult[0m[0;34m)[0m[0;34m[0m[0;34m[0m[0m
[0;32m---> 10[0;31m     [0mresult[0m[0;34m.[0m[0mset_index[0m[0;34m([0m[0maxis_labels[0m[0;34m)[0m[0;34m[0m[0;34m[0m[0m
[0m[1;32m     11[0m     [0;32mreturn[0m [0mresult[0m[0;34m[0m[0;34m[0m[0m

[0;32m/usr/share/miniconda/envs/q2book/lib/python3.6/site-packages/pandas/core/generic.py[0m in [0;36m__getattr__[0;34m(self, name)[0m
[1;32m   5139[0m             [0;32mif[0m [0mself[0m[0;34m.[0m[0m_info_axis[0m[0;34m.[0m[0m_can_hold_identifiers_and_holds_name[0m[0;34m([0m[0mname[0m[0;34m)[0m[0;34m:[0m[0;34m[0m[0;34m[0m[0m
[1;32m   5140[0m                 [0;32mreturn[0m [0mself[0m[0;34m[[0m[0mname[0m[0;34m][0m[0;34m[0m[0;34m[0m[0m
[0;32m-> 5141[0;31m             [0;32mreturn[0m [0mobject[0m[0;34m.[0m[0m__getattribute__[0m[0;34m([0m[0mself[0m[0;34m,[0m [0mname[0m[0;34m)[0m[0;34m[0m[0;34m[0m[0m
[0m[1;32m   5142[0m [0;34m[0m[0m
[1;32m   5143[0m     [0;32mdef[0m [0m__setattr__[0m[0;34m([0m[0mself[0m[0;34m,[0m [0mname[0m[0;34m:[0m [0mstr[0m[0;34m,[0m [0mvalue[0m[0;34m)[0m [0;34m->[0m [0;32mNone[0m[0;34m:[0m[0;34m[0m[0;34m[0m[0m

[0;31mAttributeError[0m: 'Series' object has no attribute 'set_index'
AttributeError: 'Series' object has no attribute 'set_index'

